<?xml version="1.0" ?>
<!-- =================================================================================== -->
<!-- |    This document was autogenerated by xacro from chassis.xacro                  | -->
<!-- |    EDITING THIS FILE BY HAND IS NOT RECOMMENDED                                 | -->
<!-- =================================================================================== -->
<robot name="chassis">
  <!-- xacro2urdf -->
  <link name="base_footprint">
    <visual>
      <geometry>
        <sphere radius="0.001"/>
      </geometry>
    </visual>
  </link>
  <link name="base_link">
    <visual>
      <geometry>
        <cylinder length="0.08" radius="0.1"/>
      </geometry>
      <origin rpy="0.0 0.0 0.0" xyz="0.0 0.0 0.0"/>
      <material name="base_color">
        <color rgba="1.0 0.5 0.5 0.5"/>
      </material>
    </visual>
  </link>
  <joint name="base2footprint" type="fixed">
    <parent link="base_footprint"/>
    <child link="base_link"/>
    <origin rpy="0.0 0.0 0.0" xyz="0.0 0.0 0.055"/>
    <axis xyz="0 0 0"/>
  </joint>
  <link name="left_wheel">
    <visual>
      <geometry>
        <cylinder length="0.015" radius="0.0325"/>
        <!-- <cylinder radius="${}" length="${}" /> -->
        <!-- <box size="${} ${} ${}" /> -->
        <!-- <sphere radius="${}" /> -->
        <!-- <mesh filename="package://simulation/meshes/autolabor_mini.stl" /> -->
      </geometry>
      <origin rpy="1.57079635 0.0 0.0" xyz="0.0 0.0 0.0"/>
      <material name="wheel_color">
        <color rgba="0.0 0.0 0.0 0.5"/>
      </material>
    </visual>
    <!-- <collision>  -->
    <!-- </collision> -->
    <!-- <Inertial> -->
    <!-- </Inertial> -->
  </link>
  <joint name="left2base" type="continuous">
    <parent link="base_link"/>
    <child link="left_wheel"/>
    <origin rpy="0.0 0.0 0.0" xyz="0.0 0.1 -0.0225"/>
    <axis xyz="0 1 0"/>
  </joint>
  <link name="right_wheel">
    <visual>
      <geometry>
        <cylinder length="0.015" radius="0.0325"/>
        <!-- <cylinder radius="${}" length="${}" /> -->
        <!-- <box size="${} ${} ${}" /> -->
        <!-- <sphere radius="${}" /> -->
        <!-- <mesh filename="package://simulation/meshes/autolabor_mini.stl" /> -->
      </geometry>
      <origin rpy="1.57079635 0.0 0.0" xyz="0.0 0.0 0.0"/>
      <material name="wheel_color">
        <color rgba="0.0 0.0 0.0 0.5"/>
      </material>
    </visual>
    <!-- <collision>  -->
    <!-- </collision> -->
    <!-- <Inertial> -->
    <!-- </Inertial> -->
  </link>
  <joint name="right2base" type="continuous">
    <parent link="base_link"/>
    <child link="right_wheel"/>
    <origin rpy="0.0 0.0 0.0" xyz="0.0 -0.1 -0.0225"/>
    <axis xyz="0 1 0"/>
  </joint>
  <link name="front_wheel">
    <visual>
      <geometry>
        <sphere radius="0.0075"/>
      </geometry>
      <origin rpy="0.0 0.0 0.0" xyz="0.0 0.0 0.0"/>
      <material name="wheel_color">
        <color rgba="1.0 0.5 0.5 0.5"/>
      </material>
    </visual>
  </link>
  <joint name="front2base" type="continuous">
    <parent link="base_link"/>
    <child link="front_wheel"/>
    <origin rpy="0.0 0.0 0.0" xyz="0.08 0.0 -0.0475"/>
    <axis xyz="1 1 1"/>
  </joint>
  <link name="back_wheel">
    <visual>
      <geometry>
        <sphere radius="0.0075"/>
      </geometry>
      <origin rpy="0.0 0.0 0.0" xyz="0.0 0.0 0.0"/>
      <material name="wheel_color">
        <color rgba="1.0 0.5 0.5 0.5"/>
      </material>
    </visual>
  </link>
  <joint name="back2base" type="continuous">
    <parent link="base_link"/>
    <child link="back_wheel"/>
    <origin rpy="0.0 0.0 0.0" xyz="-0.08 0.0 -0.0475"/>
    <axis xyz="1 1 1"/>
  </joint>
  <!-- <xacro:include filename="<xacrofile>"> -->
</robot>

